Workbook
Name 版块: [1]项目性质!$K$1:$K$7
Name 电力建设类: [2]数据源!$I$4:$I$7
Name 电力生产类: [2]数据源!$H$4:$H$7
Name 发电企业: [3]电厂!$C$2:$C$189

Sheet 统计
J1: 授权专利总体统计情况 | N1: 授权专利逐年分布情况
A2: 组别 | B2: 要求 | C2: 单位简称 | D2: 授权的管理专利（实用+发明） | E2: 公式特征 | F2: 辅助列 | G2: 情况说明 | J2: 授权专利 | K2: 申请中专利 | L2: 作废专利 | N2: 2016 | O2: 2017 | P2: 2018 | Q2: 2019 | R2: 2020 | S2: 2021 | T2: 2022 | U2: 2023 | V2: 2024
A3: 未去重 | B3: “公司1”授权的实用新型和发明专利（不考虑重复填报情况） | C3: 公司1 | D3: =COUNTIFS(专利!$A:$A,"*"&$C3&"*",专利!$D:$D,"发明",专利!$F:$F,"授权")+COUNTIFS(专利!$A:$A,"*"&$C3&"*",专利!$D:$D,"实用新型",专利!$F:$F,"授权") -> 50 | E3: 多个COUNTIFS相加 | G3: ×（适用于没有重复名称的表格） | I3: 未去重 | J3: =COUNTIFS(专利!$A:$A,"*"&$C3&"*",专利!$F:$F,"授权") -> 51 | K3: =COUNTIFS(专利!$A:$A,"*"&$C3&"*",专利!$F:$F,"受理") -> 11 | L3: {=SUM(COUNTIFS(专利!$A:$A,"*"&$C3&"*",专利!$F:$F,{"*驳回","*撤回","*终止"}))} -> 0 | N3: =COUNTIFS(专利!$A:$A,"*"&$C3&"*",专利!$F:$F,"授权",专利!$G:$G,"<="&DATE(2016,12,31)) -> 0 | O3: =COUNTIFS(专利!$A:$A,"*"&$C3&"*",专利!$F:$F,"授权",专利!$G:$G,">="&DATE(O$2,1,1),专利!$G:$G,"<="&DATE(O$2,12,31)) -> 1 | P3: =COUNTIFS(专利!$A:$A,"*"&$C3&"*",专利!$F:$F,"授权",专利!$G:$G,">="&DATE(P$2,1,1),专利!$G:$G,"<="&DATE(P$2,12,31)) -> 0 | Q3: =COUNTIFS(专利!$A:$A,"*"&$C3&"*",专利!$F:$F,"授权",专利!$G:$G,">="&DATE(Q$2,1,1),专利!$G:$G,"<="&DATE(Q$2,12,31)) -> 4 | R3: =COUNTIFS(专利!$A:$A,"*"&$C3&"*",专利!$F:$F,"授权",专利!$G:$G,">="&DATE(R$2,1,1),专利!$G:$G,"<="&DATE(R$2,12,31)) -> 1 | S3: =COUNTIFS(专利!$A:$A,"*"&$C3&"*",专利!$F:$F,"授权",专利!$G:$G,">="&DATE(S$2,1,1),专利!$G:$G,"<="&DATE(S$2,12,31)) -> 6 | T3: =COUNTIFS(专利!$A:$A,"*"&$C3&"*",专利!$F:$F,"授权",专利!$G:$G,">="&DATE(T$2,1,1),专利!$G:$G,"<="&DATE(T$2,12,31)) -> 20 | U3: =COUNTIFS(专利!$A:$A,"*"&$C3&"*",专利!$F:$F,"授权",专利!$G:$G,">="&DATE(U$2,1,1),专利!$G:$G,"<="&DATE(U$2,12,31)) -> 12 | V3: =COUNTIFS(专利!$A:$A,"*"&$C3&"*",专利!$F:$F,"授权",专利!$G:$G,">="&DATE(V$2,1,1),专利!$G:$G,"<="&DATE(V$2,12,31)) -> 7
B4: “公司1”授权的实用新型和发明专利（不考虑重复填报情况） | C4: 公司1 | D4: {=SUM(COUNTIFS(专利!$A:$A,"*"&$C4&"*",专利!$D:$D,{"发明","实用新型"},专利!$F:$F,"授权"))} -> 50 | E4: SUM + COUNTIFS + {}，整列检索 | G4: ×（适用于没有重复名称的表格） | I4: 去重后 | J4: {=SUM(IFERROR( 1/COUNTIFS( INDIRECT("专利!$A2:$A"&"1000"),"*"&$C4&"*", INDIRECT("专利!$F2:$F"&"1000"),"授权", INDIRECT("专利!$B2:$B"&"1000"),INDIRECT("专利!$B2:$B"&"1000") )* (INDIRECT("专利!$A2:$A"&"1000")=$C4)* (INDIRECT("专利!$F2:$F"&"1000")="授权"), 0))} -> 48 | K4: {=SUM(IFERROR( 1/COUNTIFS( INDIRECT("专利!$A2:$A"&"1000"),"*"&$C4&"*", INDIRECT("专利!$F2:$F"&"1000"),"受理", INDIRECT("专利!$B2:$B"&"1000"),INDIRECT("专利!$B2:$B"&"1000") )* (INDIRECT("专利!$A2:$A"&"1000")=$C4)* (INDIRECT("专利!$F2:$F"&"1000")="受理"), 0))} -> 10 | L4: {=SUM(IFERROR( 1/COUNTIFS( INDIRECT("专利!$A2:$A"&"1000"),"*"&$C4&"*", INDIRECT("专利!$F2:$F"&"1000"),{"*驳回","*撤回","*终止"}, INDIRECT("专利!$B2:$B"&"1000"),INDIRECT("专利!$B2:$B"&"1000") )* (INDIRECT("专利!$A2:$A"&"1000")=$C4)* ( ISNUMBER(SEARCH("驳回",INDIRECT("专利!$F2:$F"&"1000"))) + ISNUMBER(SEARCH("撤回", INDIRECT("专利!$F2:$F"&"1000"))) + ISNUMBER(SEARCH("终止", INDIRECT("专利!$F2:$F"&"1000"))) > 0), 0))} -> 0 | N4: {=SUM(IFERROR( 1/COUNTIFS( INDIRECT("专利!$A2:$A"&"1000"),"*"&$C4&"*", INDIRECT("专利!$F2:$F"&"1000"),"授权", INDIRECT("专利!$G2:$G"&"1000"),"<="&DATE(2016,12,31), INDIRECT("专利!$B2:$B"&"1000"),INDIRECT("专利!$B2:$B"&"1000") )* (INDIRECT("专利!$A2:$A"&"1000")=$C4)* (INDIRECT("专利!$G2:$G"&"1000")<=DATE(2016,12,31))* (INDIRECT("专利!$F2:$F"&"1000")="授权"), 0))} -> 0 | O4: {=SUM(IFERROR( 1/COUNTIFS( INDIRECT("专利!$A2:$A"&"1000"),"*"&$C4&"*", INDIRECT("专利!$F2:$F"&"1000"),"授权", INDIRECT("专利!$G2:$G"&"1000"),">="&DATE(O$2,1,1), INDIRECT("专利!$G2:$G"&"1000"),"<="&DATE(O$2,12,31), INDIRECT("专利!$B2:$B"&"1000"),INDIRECT("专利!$B2:$B"&"1000") )* (INDIRECT("专利!$A2:$A"&"1000")=$C4)* (INDIRECT("专利!$G2:$G"&"1000")>=DATE(O$2,1,1))* (INDIRECT("专利!$G2:$G"&"1000")<=DATE(O$2,12,31))* (INDIRECT("专利!$F2:$F"&"1000")="授权"), 0))} -> 1 | P4: {=SUM(IFERROR( 1/COUNTIFS( INDIRECT("专利!$A2:$A"&"1000"),"*"&$C4&"*", INDIRECT("专利!$F2:$F"&"1000"),"授权", INDIRECT("专利!$G2:$G"&"1000"),">="&DATE(P$2,1,1), INDIRECT("专利!$G2:$G"&"1000"),"<="&DATE(P$2,12,31), INDIRECT("专利!$B2:$B"&"1000"),INDIRECT("专利!$B2:$B"&"1000") )* (INDIRECT("专利!$A2:$A"&"1000")=$C4)* (INDIRECT("专利!$G2:$G"&"1000")>=DATE(P$2,1,1))* (INDIRECT("专利!$G2:$G"&"1000")<=DATE(P$2,12,31))* (INDIRECT("专利!$F2:$F"&"1000")="授权"), 0))} -> 0 | Q4: {=SUM(IFERROR( 1/COUNTIFS( INDIRECT("专利!$A2:$A"&"1000"),"*"&$C4&"*", INDIRECT("专利!$F2:$F"&"1000"),"授权", INDIRECT("专利!$G2:$G"&"1000"),">="&DATE(Q$2,1,1), INDIRECT("专利!$G2:$G"&"1000"),"<="&DATE(Q$2,12,31), INDIRECT("专利!$B2:$B"&"1000"),INDIRECT("专利!$B2:$B"&"1000") )* (INDIRECT("专利!$A2:$A"&"1000")=$C4)* (INDIRECT("专利!$G2:$G"&"1000")>=DATE(Q$2,1,1))* (INDIRECT("专利!$G2:$G"&"1000")<=DATE(Q$2,12,31))* (INDIRECT("专利!$F2:$F"&"1000")="授权"), 0))} -> 2 | R4: {=SUM(IFERROR( 1/COUNTIFS( INDIRECT("专利!$A2:$A"&"1000"),"*"&$C4&"*", INDIRECT("专利!$F2:$F"&"1000"),"授权", INDIRECT("专利!$G2:$G"&"1000"),">="&DATE(R$2,1,1), INDIRECT("专利!$G2:$G"&"1000"),"<="&DATE(R$2,12,31), INDIRECT("专利!$B2:$B"&"1000"),INDIRECT("专利!$B2:$B"&"1000") )* (INDIRECT("专利!$A2:$A"&"1000")=$C4)* (INDIRECT("专利!$G2:$G"&"1000")>=DATE(R$2,1,1))* (INDIRECT("专利!$G2:$G"&"1000")<=DATE(R$2,12,31))* (INDIRECT("专利!$F2:$F"&"1000")="授权"), 0))} -> 1 | S4: {=SUM(IFERROR( 1/COUNTIFS( INDIRECT("专利!$A2:$A"&"1000"),"*"&$C4&"*", INDIRECT("专利!$F2:$F"&"1000"),"授权", INDIRECT("专利!$G2:$G"&"1000"),">="&DATE(S$2,1,1), INDIRECT("专利!$G2:$G"&"1000"),"<="&DATE(S$2,12,31), INDIRECT("专利!$B2:$B"&"1000"),INDIRECT("专利!$B2:$B"&"1000") )* (INDIRECT("专利!$A2:$A"&"1000")=$C4)* (INDIRECT("专利!$G2:$G"&"1000")>=DATE(S$2,1,1))* (INDIRECT("专利!$G2:$G"&"1000")<=DATE(S$2,12,31))* (INDIRECT("专利!$F2:$F"&"1000")="授权"), 0))} -> 5 | T4: {=SUM(IFERROR( 1/COUNTIFS( INDIRECT("专利!$A2:$A"&"1000"),"*"&$C4&"*", INDIRECT("专利!$F2:$F"&"1000"),"授权", INDIRECT("专利!$G2:$G"&"1000"),">="&DATE(T$2,1,1), INDIRECT("专利!$G2:$G"&"1000"),"<="&DATE(T$2,12,31), INDIRECT("专利!$B2:$B"&"1000"),INDIRECT("专利!$B2:$B"&"1000") )* (INDIRECT("专利!$A2:$A"&"1000")=$C4)* (INDIRECT("专利!$G2:$G"&"1000")>=DATE(T$2,1,1))* (INDIRECT("专利!$G2:$G"&"1000")<=DATE(T$2,12,31))* (INDIRECT("专利!$F2:$F"&"1000")="授权"), 0))} -> 20 | U4: {=SUM(IFERROR( 1/COUNTIFS( INDIRECT("专利!$A2:$A"&"1000"),"*"&$C4&"*", INDIRECT("专利!$F2:$F"&"1000"),"授权", INDIRECT("专利!$G2:$G"&"1000"),">="&DATE(U$2,1,1), INDIRECT("专利!$G2:$G"&"1000"),"<="&DATE(U$2,12,31), INDIRECT("专利!$B2:$B"&"1000"),INDIRECT("专利!$B2:$B"&"1000") )* (INDIRECT("专利!$A2:$A"&"1000")=$C4)* (INDIRECT("专利!$G2:$G"&"1000")>=DATE(U$2,1,1))* (INDIRECT("专利!$G2:$G"&"1000")<=DATE(U$2,12,31))* (INDIRECT("专利!$F2:$F"&"1000")="授权"), 0))} -> 12 | V4: {=SUM(IFERROR( 1/COUNTIFS( INDIRECT("专利!$A2:$A"&"1000"),"*"&$C4&"*", INDIRECT("专利!$F2:$F"&"1000"),"授权", INDIRECT("专利!$G2:$G"&"1000"),">="&DATE(V$2,1,1), INDIRECT("专利!$G2:$G"&"1000"),"<="&DATE(V$2,12,31), INDIRECT("专利!$B2:$B"&"1000"),INDIRECT("专利!$B2:$B"&"1000") )* (INDIRECT("专利!$A2:$A"&"1000")=$C4)* (INDIRECT("专利!$G2:$G"&"1000")>=DATE(V$2,1,1))* (INDIRECT("专利!$G2:$G"&"1000")<=DATE(V$2,12,31))* (INDIRECT("专利!$F2:$F"&"1000")="授权"), 0))} -> 7
B5: “公司1”授权的实用新型和发明专利（不考虑重复填报情况） | C5: 公司3 | D5: =SUM( COUNTIFS( INDIRECT("专利!$A1:$A"&F5),"*"&$C5&"*", INDIRECT("专利!$D1:$D"&F5),{"发明","实用新型"}, INDIRECT("专利!$F1:$F"&F5),"授权") ) -> 5 | E5: SUM + COUNTIFS + {} +INDIRECT，依据辅助列限定检索范围 | F5: =COUNTA(专利!B:B)+1 -> 136 | G5: ×（适用于没有重复名称的表格）
A6: 去重后 | B6: “公司1”授权的实用新型和发明专利（根据专利名称排除重复填报的条目） | C6: 公司1 | D6: {=SUM(IFERROR( 1/COUNTIFS( INDIRECT("专利!$A2:$A"&F6),"*"&$C6&"*", INDIRECT("专利!$D2:$D"&F6),{"发明","实用新型"}, INDIRECT("专利!$F2:$F"&F6),"授权", INDIRECT("专利!$B2:$B"&F6),INDIRECT("专利!$B2:$B"&F6) )* (INDIRECT("专利!$A2:$A"&F6)=C6)* (INDIRECT("专利!$D2:$D"&F6)={"发明","实用新型"})* (INDIRECT("专利!$F2:$F"&F6)="授权"), 0))} -> 47 | E6: 数组公式 + SUM + IFERROR + 1/COUNTIFS + {}，依据辅助列限定检索范围，通过 * 去重 | F6: =COUNTA(专利!B:B)+1 -> 136 | G6: 建议使用 | H6: {=SUM(IFERROR( 1/COUNTIFS( INDIRECT("专利!$A2:$A"&F6),"*"&$C6&"*", INDIRECT("专利!$D2:$D"&F6),{"发明","实用新型"}, INDIRECT("专利!$F2:$F"&F6),"授权", INDIRECT("专利!$B2:$B"&F6),INDIRECT("专利!$B2:$B"&F6) ), 0))} -> 47.833333 | I6: =INT(H6) -> 47 | J6: {=SUM(IFERROR( 1/COUNTIFS( INDIRECT("专利!$C2:$C"&F6),"*"&$C6&"*", INDIRECT("专利!$D2:$D"&F6),{"发明","实用新型"}, INDIRECT("专利!$F2:$F"&F6),"授权", INDIRECT("专利!$B2:$B"&F6),INDIRECT("专利!$B2:$B"&F6) )* (ISNUMBER(SEARCH(C6,INDIRECT("专利!$C2:$C"&F6))))* (INDIRECT("专利!$D2:$D"&F6)={"发明","实用新型"})* (INDIRECT("专利!$F2:$F"&F6)="授权"), 0))} -> 47 | K6: ←不对A列统计，对C列统计【有待验证是否会模糊匹配其他单位名称】
B7: “公司1”授权的实用新型和发明专利（根据专利名称排除重复填报的条目） | C7: 公司1 | D7: {=SUMPRODUCT(IFERROR( 1/COUNTIFS( INDIRECT("专利!$A2:$A"&F7),"*"&$C7&"*", INDIRECT("专利!$D2:$D"&F7),{"发明","实用新型"}, INDIRECT("专利!$F2:$F"&F7),"授权", INDIRECT("专利!$B2:$B"&F7),INDIRECT("专利!$B2:$B"&F7) )* (INDIRECT("专利!$A2:$A"&F7)=C7)* (INDIRECT("专利!$D2:$D"&F7)={"发明","实用新型"})* (INDIRECT("专利!$F2:$F"&F7)="授权"), 0))} -> 47 | E7: 数组公式 + SUMPRODUCT + IFERROR + 1/COUNTIFS + {}，依据辅助列限定检索范围，通过 * 去重 | F7: =COUNTA(专利!B:B)+1 -> 136 | G7: 备用推荐 | H7: {=SUMPRODUCT(IFERROR(1/COUNTIFS(INDIRECT("专利!$A2:$A"&F7),"*"&$C7&"*",INDIRECT("专利!$D2:$D"&F7),{"发明","实用新型"},INDIRECT("专利!$F2:$F"&F7),"授权",INDIRECT("专利!$B2:$B"&F7),INDIRECT("专利!$B2:$B"&F7)),0))} -> 47.833333 | I7: =INT(H7) -> 47
B8: “公司1”授权的第一权利人实用新型和发明专利（根据专利名称排除重复填报的条目） | C8: 公司1 | D8: {=SUMPRODUCT(IFERROR( 1/COUNTIFS( INDIRECT("专利!$A2:$A"&F8),"*"&$C8&"*", INDIRECT("专利!$D2:$D"&F8),{"发明","实用新型"}, INDIRECT("专利!$F2:$F"&F8),"授权", INDIRECT("专利!$H2:$H"&F8),"是", INDIRECT("专利!$B2:$B"&F8),INDIRECT("专利!$B2:$B"&F8) )* (INDIRECT("专利!$A2:$A"&F8)=C8)* (INDIRECT("专利!$D2:$D"&F8)={"发明","实用新型"})* (INDIRECT("专利!$F2:$F"&F8)="授权")* (INDIRECT("专利!$H2:$H"&F8)="是"), 0))} -> 46 | E8: 数组公式 + SUMPRODUCT + IFERROR + 1/COUNTIFS + {}，依据辅助列限定检索范围，通过 * 去重 | F8: =COUNTA(专利!B:B)+1 -> 136 | G8: 增加限制条件时，2个地方对应添加限制条件即可 | H8: {=SUMPRODUCT(IFERROR(1/COUNTIFS(INDIRECT("专利!$A2:$A"&F8),"*"&$C8&"*",INDIRECT("专利!$D2:$D"&F8),{"发明","实用新型"},INDIRECT("专利!$F2:$F"&F8),"授权",INDIRECT("专利!$H2:$H"&F8),"是",INDIRECT("专利!$B2:$B"&F8),INDIRECT("专利!$B2:$B"&F8)),0))} -> 46.833333 | I8: =INT(H8) -> 46

Sheet 专利
A2: 单位 | B2: 专利名称 | C2: 申请/专利权人 | D2: 专利类型 | E2: 申请日期 | F2: 法律状态 | G2: 授权日期 | H2: 第一权利人 | I2: 经费投入 | J2: 备注
A3: 公司1 | B3: 专利1 | C3: 公司1 | D3: 外观设计 | E3: 42641 | F3: 授权 | G3: 42830 | H3: 是 | I3: 1500
A4: 公司1 | B4: 专利2 | C4: 公司1 | D4: 实用新型 | E4: 43583 | F4: 授权 | G4: 43812 | H4: 是 | I4: 4000
A5: 公司1 | B5: 专利3 | C5: 公司1 | D5: 实用新型 | E5: 43583 | F5: 授权 | G5: 43812 | H5: 是 | I5: 4000
A6: 公司1 | B6: 专利3 | C6: 公司1 | D6: 实用新型 | E6: 43583 | F6: 专利权许可 | G6: 43812 | H6: 是 | I6: 4000 | J6: 重复的记录（新状态）
J7: 空行
A8: 公司1 | B8: 专利3 | C8: 公司1 | D8: 实用新型 | E8: 43583 | F8: 授权 | G8: 43812 | H8: 是 | I8: 4000 | J8: 重复的授权记录
A9: 公司1 | B9: 专利3 | C9: 公司1 | D9: 实用新型 | E9: 43583 | F9: 授权 | G9: 43812 | H9: 是 | I9: 4000 | J9: 重复的授权记录
A10: 公司1 | B10: 专利4 | C10: 公司1 | D10: 实用新型 | E10: 43686 | F10: 授权 | G10: 43942 | H10: 否 | I10: 4000
A11: 公司1 | B11: 专利5 | C11: 公司1 | D11: 实用新型 | E11: 44123 | F11: 授权 | G11: 44344 | H11: 是 | I11: 4000
A12: 公司1 | B12: 专利5 | C12: 公司1 | D12: 实用新型 | E12: 44123 | F12: 授权 | G12: 44344 | H12: 是 | I12: 4000 | J12: 重复的授权记录
A13: 公司1 | B13: 专利5 | C13: 公司1 | D13: 实用新型 | E13: 44123 | F13: 专利权转移 | G13: 44344 | H13: 是 | I13: 4000 | J13: 重复的记录
A14: 公司1 | B14: 专利6 | C14: 公司1 | D14: 实用新型 | E14: 44123 | F14: 授权 | G14: 44351 | H14: 是 | I14: 4000
A15: 公司1 | B15: 专利7 | C15: 公司1 | D15: 实用新型 | E15: 44159 | F15: 授权 | G15: 44488 | H15: 是 | I15: 4000
A16: 公司1 | B16: 专利8 | C16: 公司1 | D16: 发明专利 | E16: 44404 | F16: 受理 | H16: 是 | I16: 2000
A17: 公司1 | B17: 专利8 | C17: 公司1 | D17: 发明专利 | E17: 44404 | F17: 受理 | H17: 是 | I17: 2000 | J17: 重复的受理记录
A18: 公司1 | B18: 专利9 | C18: 公司1 | D18: 发明专利 | E18: 44404 | F18: 受理 | H18: 是 | I18: 2000
A19: 公司1 | B19: 专利10 | C19: 公司1 | D19: 发明专利 | E19: 44439 | F19: 受理 | H19: 是 | I19: 2000
A20: 公司1 | B20: 专利11 | C20: 公司1 | D20: 发明专利 | E20: 44483 | F20: 受理 | H20: 是 | I20: 2000
A21: 公司1 | B21: 专利12 | C21: 公司1 | D21: 实用新型 | E21: 44278 | F21: 授权 | G21: 44498 | H21: 是 | I21: 4000
A22: 公司1 | B22: 专利13 | C22: 公司1 | D22: 实用新型 | E22: 44370 | F22: 授权 | G22: 44831 | H22: 是 | I22: 4000
A23: 公司1 | B23: 专利14 | C23: 公司1 | D23: 实用新型 | E23: 44370 | F23: 授权 | G23: 44831 | H23: 是 | I23: 4000
A24: 公司1 | B24: 专利15 | C24: 公司1 | D24: 实用新型 | E24: 44375 | F24: 授权 | G24: 44554 | H24: 是 | I24: 4000
A25: 公司1 | B25: 专利16 | C25: 公司1 | D25: 实用新型 | E25: 44375 | F25: 授权 | G25: 44831 | H25: 是 | I25: 4000
A26: 公司1 | B26: 专利17 | C26: 公司1 | D26: 实用新型 | E26: 44404 | F26: 授权 | G26: 44572 | H26: 是 | I26: 4000
A27: 公司1 | B27: 专利18 | C27: 公司1 | D27: 实用新型 | E27: 44412 | F27: 授权 | G27: 44568 | H27: 是 | I27: 4000
A28: 公司1 | B28: 专利19 | C28: 公司1 | D28: 实用新型 | E28: 44413 | F28: 授权 | G28: 44572 | H28: 是 | I28: 4000
A29: 公司1 | B29: 专利20 | C29: 公司1 | D29: 实用新型 | E29: 44439 | F29: 授权 | G29: 44831 | H29: 是 | I29: 4000
A30: 公司1 | B30: 专利21 | C30: 公司1 | D30: 实用新型 | E30: 44439 | F30: 授权 | G30: 44873 | H30: 是 | I30: 4000
A31: 公司1 | B31: 专利22 | C31: 公司1 | D31: 实用新型 | E31: 44561 | F31: 授权 | G31: 44813 | H31: 是 | I31: 4000
A32: 公司1 | B32: 专利23 | C32: 公司1、公司10 | D32: 发明专利 | E32: 44726 | F32: 受理 | H32: 是 | I32: 2000
A33: 公司1 | B33: 专利24 | C33: 公司1 | D33: 发明专利 | E33: 44775 | F33: 受理 | H33: 是 | I33: 2000
A34: 公司1 | B34: 专利25 | C34: 公司1 | D34: 实用新型 | E34: 44708 | F34: 授权 | G34: 44817 | H34: 是 | I34: 4000
A35: 公司1 | B35: 专利26 | C35: 公司1 | D35: 实用新型 | E35: 44711 | F35: 授权 | G35: 44911 | H35: 是 | I35: 4000
A36: 公司1 | B36: 专利27 | C36: 公司1 | D36: 实用新型 | E36: 44725 | F36: 授权 | G36: 44915 | H36: 是 | I36: 4000
A37: 公司1 | B37: 专利28 | C37: 公司1、公司10 | D37: 实用新型 | E37: 44725 | F37: 授权 | G37: 44880 | H37: 是 | I37: 4000
A38: 公司1 | B38: 专利29 | C38: 公司1、公司10 | D38: 实用新型 | E38: 44723 | F38: 授权 | G38: 44838 | H38: 是 | I38: 4000
A39: 公司1 | B39: 专利30 | C39: 公司1 | D39: 实用新型 | E39: 44729 | F39: 授权 | G39: 44911 | H39: 是 | I39: 4000
A40: 公司1 | B40: 专利31 | C40: 公司1 | D40: 实用新型 | E40: 44749 | F40: 授权 | G40: 44873 | H40: 是 | I40: 4000
A41: 公司1 | B41: 专利32 | C41: 公司1 | D41: 实用新型 | E41: 44764 | F41: 授权 | G41: 44901 | H41: 是 | I41: 4000
...
